Workbook

Sheet Etat des lieux
A1: Avancement
A3: Validée | B3: =COUNTIFS('Datalayer BPCE vtravail'!E2:E155,"Validée") -> 77
A4: A préciser | B4: =COUNTIFS('Datalayer BPCE vtravail'!E3:E209,"A préciser") -> 0
A5: A implémenter | B5: =COUNTIFS('Datalayer BPCE vtravail'!E4:E210,"A implémenter") -> 0
A6: A supprimer | B6: =COUNTIFS('Datalayer BPCE vtravail'!E5:E211,"A supprimer") -> 79
A7: Reste à analyser | B7: =COUNTIFS('Datalayer BPCE vtravail'!E6:E212,"") -> 4

Sheet Repérages report suite
B1: Statut | C1: Nom de la report suite | E1: CE | F1: principale report suite, sur laquelle les variables devraient être
B2: Archivé | C2: bpcebpcetestdev
B3: Archivé | C3: bpceriarwddev
B4: Archivé | C4: bpcetemplate
B5: B2B & institutionnel | C5: bpce89c3production
B6: B2B & institutionnel | C6: bpce89c3recette
B7: B2B & institutionnel | C7: bpceapp.pulsar.89c3..recette
B8: CE | C8: bpceceprod11315
B9: CE | C9: bpceceprod11425
B10: CE | C10: bpceceprod12135
B11: CE | C11: bpceceprod12579
B12: CE | C12: bpceceprod13135
B13: CE | C13: bpceceprod13335
... B48: Paylib | C48: bpceappexternerecette

Sheet Audit variables Adobe
B1: Introduction au document
B3: Définition du OK : nom est à la norme dans Adobe Analytics et dans la doc. La doc et Adobe sont cohérents.
B4: Définition du Erreur : une correction doit être apportée (A corriger), ou une incertitude demeure dans les specs qui doit être confirmée (A clarifier)
B5: Certaines actions ne génèrent pas d'erreur, mais génèrent cependant de l'incertitude, et sont marquées par une action A clarifier
C7: CE | F7: BP | I7: Erreur globale BP | J7: Mapping
A8: Numéro variable | B8: Nom variable dans la documentation | C8: Verdict | D8: Action | E8: Commentaire | F8: Verdict2 | G8: Action2 | H8: Commentaire2 | I8: Tous les noms doivent être mis à la norme "nom de la variable (propX/evarX/eventX)"
A9: prop1 | B9: Code Etablissement Client (prop1) | C9: OK | F9: OK
A10: prop2 | B10: Id Client (prop2) | C10: OK | F10: OK
A11: prop3 | B11: Statut Client (prop3) | C11: OK | F11: OK
A12: prop4 | B12: Marché Client (prop4) | C12: OK | F12: OK
A13: prop5 | B13: Code réduit Etablissement de la page (prop5) | C13: OK | F13: OK
A14: prop6 | B14: Type Applicatif (prop6) | C14: OK | F14: OK
A15: prop7 | B15: Nom de l applicatif (prop7) | C15: OK | F15: OK
A16: prop8 | B16: Marché de navigation (prop8) | C16: OK | F16: OK
A17: prop9 | B17: Univers de navigation (prop9) | C17: OK | F17: OK
A18: prop10 | B18: Type de la page (prop10) | C18: OK | F18: OK
A19: prop11 | B19: Is ABTesting (prop11) | C19: OK | F19: OK
A20: prop12 | B20: Id ABTesting(prop12) | C20: OK | F20: OK
... A27: prop19 | B27: Nom de la tuile (prop19) | C27: OK | F27: OK
A28: prop20 | B28: Home - libellé de toutes les vignettes (prop20) | C28: Erreur | D28: A clarifier | E28: Renseignée mais en doublon par rappor tà la list var 1 et souvent tronquée faute nb caractère suffisant. Pas trouvées dans le datalayer pour voir prioppriété et variable (compléter doc interne) | F28: Erreur | G28: A clarifier | H28: Renseignée mais en doublon par rappor tà la list var 1 et souvent tronquée faute nb caractère suffisant. Pas trouvées dans le datalayer pour voir prioppriété et variable (compléter doc interne)
A29: prop21 | B29: Home - libellé vignette principale (prop21) | C29: Erreur | D29: A clarifier | E29: Disabled, utile ? Doublon par rapport à la list var 1. Pas trouvées dans le datalayer pour voir prioppriété et variable (compléter doc interne) | F29: Erreur | G29: A clarifier | H29: Disabled, utile ? Doublon par rapport à la list var 1. Pas trouvées dans le datalayer pour voir prioppriété et variable (compléter doc interne). Signalement coquille : incohérent entre BP prod et le reste (BP recette et CE), variable est "Code Etablissement BP" + est disabled vs "Home - libelle vignette principale"
A30: prop22 | B30: Age(s) et Lien de parenté (prop22) | C30: Erreur | D30: A réutiliser pour EDL | E30: Donnee personnelle, à retirer ? Renseignée en 2017, plus en 2018 ou 2019. | F30: Erreur | G30: A réutiliser pour EDL | H30: Donnee personnelle, à retirer ? Renseignée en 2017, plus en 2018 ou 2019.
A31: prop23 | B31: Temps de chargement de la page | C31: Erreur | D31: A trancher (abandonner deux propositions et notifier Natixis Assurance) | E31: Conflit ==> dans CE c'est "Type de virement (prop23)", dans 89c3 c'est "Auto : infos" (repris par Natixis dans la prop75), et doc centrale c'est "Temps de chargement de la page". A conserver pour historique ? | F31: Erreur | G31: A trancher (abandonner deux propositions et notifier Natixis Assurance) | H31: Conflit ==> dans Adobe c'est "Auto : infos" (repris par Natixis dans la prop75), et doc centrale c'est "Temps de chargement de la page". A conserver pour historique ?
A32: prop24 | B32: type de dossier | C32: Erreur | D32: A trancher (abandonner deux propositions et notifier Natixis Assurance) | E32: Conflit ==> dans CE c'est "Montant du virement (prop24)", dans 89c3 c'est "Auto : infos" (repris par Natixis dans la prop75) et doc centrale c'est "type de dossier". A conserver pour historique ? | F32: Erreur | G32: A trancher (abandonner deux propositions et notifier Natixis Assurance) | H32: Conflit ==> dans Adobe c'est "Auto : infos" (repris par Natixis dans la prop75), et doc centrale c'est "type dossier". A conserver pour historique ?
A33: prop25 | B33: "type de document Auto: Assureur précédent (prop25)" | C33: Erreur | D33: A conserver/supprimer (notifier Natixis Assurance) ? | E33: Conflit ==> dans Adobe c'est "Auto infos" et dans doc centrale "type de document" non réutilisées par Natixis car pas représentatives des écrans pour le nouveau parcours. Actuellement disabled. A conserver pour historique ? | F33: Erreur | G33: A conserver/supprimer (notifier Natixis Assurance) ? | H33: Conflit ==> dans Adobe c'est "Auto infos" et dans doc centrale "type de document" non réutilisées par Natixis car pas représentatives des écrans pour le nouveau parcours. Actuellement disabled. A conserver pour historique ?
A34: prop26 | B34: MRH: type résidence; monument; dependance; nb pièces; nb chambre; superficie; dev durable; jacuzzi; piscine (prop26) | C34: Erreur | D34: A conserver/supprimer (notifier Natixis Assurance) ? | E34: MRH infos, non réutilisées par Natixis car pas représentatives des écrans pour le nouveau parcours. Actuellement disabled. A conserver pour historique ? | F34: Erreur | G34: A conserver/supprimer (notifier Natixis Assurance) ? | H34: MRH infos, non réutilisées par Natixis car pas représentatives des écrans pour le nouveau parcours. Actuellement disabled. A conserver pour historique ?
A35: prop27 | B35: MRH: souhaite assurer pour; occupant scolarise moins 25ans; choix formule (prop27) | C35: Erreur | D35: A conserver/supprimer (notifier Natixis Assurance) ? | E35: MRH infos, non réutilisées par Natixis car pas représentatives des écrans pour le nouveau parcours. Actuellement disabled. A conserver pour historique ? | F35: Erreur | G35: A conserver/supprimer (notifier Natixis Assurance) ? | H35: MRH infos, non réutilisées par Natixis car pas représentatives des écrans pour le nouveau parcours. Actuellement disabled. A conserver pour historique ?
A36: prop28 | B36: MRH: année construction; nb bénéficiaires; ages bénéficiaires (prop28) | C36: Erreur | D36: A conserver/supprimer (notifier Natixis Assurance) ? | E36: MRH infos, non réutilisées par Natixis car pas représentatives des écrans pour le nouveau parcours. Actuellement disabled. A conserver pour historique ? | F36: Erreur | G36: A conserver/supprimer (notifier Natixis Assurance) ? | H36: MRH infos, non réutilisées par Natixis car pas représentatives des écrans pour le nouveau parcours. Actuellement disabled. A conserver pour historique ?
A37: prop29 | B37: MRH: Code postal; type Habitation; NB pièces; Vous etes; type résidence; Mes attentes (prop29) | C37: Erreur | D37: A conserver/supprimer (notifier Natixis Assurance) ? | E37: MRH infos, non réutilisées par Natixis car pas représentatives des écrans pour le nouveau parcours. Actuellement disabled. A conserver pour historique ? | F37: Erreur | G37: A conserver/supprimer (notifier Natixis Assurance) ? | H37: MRH infos, non réutilisées par Natixis car pas représentatives des écrans pour le nouveau parcours. Actuellement disabled. A conserver pour historique ?
A38: prop30 | B38: Résultat nul (prop30) | C38: OK | F38: OK
A39: prop31 | B39: Pagename (prop31) | C39: OK | D39: A clarifier | E39: Règle de gestion manquante | F39: OK | G39: A clarifier | H39: Règle de gestion manquante
A40: prop32 | B40: Pagename page précédente (prop32) | C40: OK | D40: A clarifier | E40: Règle de gestion manquante | F40: OK | G40: A clarifier | H40: Règle de gestion manquante
A41: prop33 | B41: Libellé clic page précédente (prop33) | C41: OK | D41: A clarifier | E41: Règle de gestion manquante | F41: OK | G41: A clarifier | H41: Règle de gestion manquante
A42: prop34 | B42: Banner (prop34) | C42: OK | F42: OK
A43: prop35 | B43: Nombre de cartes actives differentes (prop35) | C43: OK | F43: OK
A44: prop36 | B44: Nombre de cartes opposées différentes (prop36) | C44: OK | F44: OK
A45: prop37 | B45: Nombre de cartes commandées ou expédiées (prop37) | C45: OK | F45: OK
A46: prop38 | B46: Nombre de cartes actives et verrouillées temporairement (prop38) | C46: OK | F46: OK
A47: prop39 | B47: Nombre de cartes actives et paiements en ligne désactivés (prop39) | C47: OK | F47: OK
A48: prop40 | B48: Nombre de cartes actives et paiements a l etranger desactivés (prop40) | C48: OK | F48: OK
...

Sheet Echantillon valeurs BP
B1: BP
A3: prop4 | B3: prop7 | C3: prop8 | E3: prop9 | H3: prop10 | K3: prop14 | L3: prop15 | M3: prop16 | O3: prop17 | R3: prop18 | U3: prop 19 | V3: prop 20 | W3: prop 22 | X3: prop 30 | Y3: prop 31 | Z3: evar 1 | AA3: evar 2 | AB3: evar 3 | AC3: evar 4 | AD3: evar 5 | AE3: evar 6 | AH3: evar 14 | AI3: evar 27 | AJ3: evar 30 | AK3: evar 31 | AL3: evar 32 | AM3: evar 33 | AN3: evar 34 | AO3: evar 35 | AP3: evar 36 | AQ3: evar 37 | AR3: evar 38 | AS3: evar 39 | AT3: evar 45 | AU3: evar 46 | AV3: evar 50
E4: Démêler ce qui relève du scrap, de ce qui est implémenté en dur | H4: inutilisable d'un point de vue analyse | K4: Valeurs à vocation à être adaptatives (+10K valeurs) | O4: 535 valeurs, ne correspond pas à l'attendun (probablement objet d'un scrapping) | U4: pas remontée, aucun référentiel de valeurs | V4: pas remontée, aucun référentiel de valeurs | W4: pas remontée, aucun référentiel de valeurs | X4: pas remontée, aucun référentiel de valeurs | Y4: Valeurs à vocation à être adaptatives (+10K valeurs) | Z4: ISO à prop1 | AA4: ISO à prop2 | AB4: ISO à prop3 | AC4: ISO à prop4 | AD4: Valeurs à vocation à être adaptatives (14K valeurs) | AE4: Liste de valeurs doivent être fixes, renseignées dans consolidé | AH4: ISO à prop14 | Valeurs à vocation à être adaptatives (78 valeurs, sensément exhaustives sur les applicatifs) | AI4: pas remontée, aucun référentiel de valeurs | AU4: pas remontée, aucun référentiel de valeurs | AV4: Valeurs à vocation à être adaptatives
A5: particulier | B5: selfcare | C5: particulier | D5: 15798451 | E5: accompagner | F5: 69 | G5: agences et distributeurs | H5: accueil | I5: 40206136 | J5: conseil | K5: virement | L5: 0 | M5: transactionnel | N5: 4209082103 | O5: banque à distance | P5: 410923 | Q5: assurance | R5: cyberplus | S5: 270507 | T5: assepargne | AD5: validation | AE5: navigation | AF5: 86406361 | AG5: action | AH5: virement
A6: particuliers | B6: tunnel | C6: particuliers | D6: 10828791 | E6: accueil | F6: 20665188 | G6: assistance | H6: acces et securite | I6: 24 | J6: consultation | K6: credit immo | L6: 100 | M6: Commercial | N6: 615808020 | O6: accéder à votre banque 24h24 7 jours7 | P6: 621 | Q6: bancarisation | R6: 3d secure | S6: 55 | T6: assurance 2 roues | W6: =CONCATENATE(U6," ",V6) | AD6: nouveau virement | AE6: action | AF6: 3360046 | AG6: annuler | AH6: Devis Auto
A7: fonction publique | B7: harvest | C7: fonction publique | D7: 4432834 | E7: aider et transmettre | F7: 1326 | G7: assurer | H7: accueil marche | I7: 339759 | J7: contact | K7: ajout beneficiaire | L7: 22.1 | M7: interne | N7: 12611021 | O7: accéder à votre banque 24h24 7jours7 | P7: 8555 | Q7: credit conso | R7: accompagnement de la clientele fragile financierement | S7: 579 | T7: assurance auto | W7: =CONCATENATE(U7," ",V7) | AD7: consulter notifications | AE7: validation | AF7: 2130033 | AG7: cta | AH7: rendez vous en ligne
A8: artisans commerçants | B8: store 89c3 | C8: artisans commerçants | D8: 3014242 | E8: aider protéger et transmettre | F8: 87 | G8: au quotidien | H8: accueil univers | I8: 141857 | J8: document | K8: sim credit conso | L8: … | N8: 30435 | O8: accompagnement start-up | P8: 68 | Q8: credit immo | R8: accompagnement start-up | S8: 62 | T8: assurance emprunteur | W8: =CONCATENATE(U8," ",V8) | AD8: effectuer virement externe | AE8: cta | AF8: 205393 | AG8: envoyer | AH8: credit immo
A9: gestion privée | B9: hub digital | C9: gestion privée | D9: 1651975 | E9: anticiper les imprévus | F9: 2007 | G9: banque au quotidien et assurance | H9: accueilexpertise | I9: 1 | J9: edito | K9: demande rdv | L9: … | N9: 9126 | O9: accroître la performance | P9: 47 | Q9: credit pro | R9: actiflow encaissements | S9: 107 | T9: assurance moyen paiement | W9: =CONCATENATE(U9," ",V9) | AD9: ne sais pas | AE9: ajout | AF9: 66692 | AG9: menu | AH9: …
A10: entreprises | B10: cyber | C10: entreprises | D10: 1176493 | E10: assurance | F10: 27313 | G10: connexion | H10: actualite | I10: 4929 | J10: erreur | K10: virement paylib | L10: … | N10: 2826 | O10: acheter sa résidence principale | P10: 268 | Q10: epargne financiere | R10: affinea | S10: 1988 | T10: assurance mrh | W10: =CONCATENATE(U10," ",V10) | AD10: en détail | AE10: valider | AF10: 65164 | AG10: navigation | AH10: …
A11: professions libérales | B11: ecommerce | C11: professions libérales | D11: 932918 | E11: assurer | F11: 69006 | G11: contact | H11: avis | I11: 3 | J11: faq | K11: credit pro | N11: 1846 | O11: acheter un bien immobilier | P11: 778 | Q11: epargne liquide | R11: agrilismat | S11: 362 | T11: assurance resp civile | W11: =CONCATENATE(U11," ",V11) | AD11: consulter alertes | AE11: supprimer | AF11: 9347 | AG11: plus tard | AH11: …
A12: jeunes actifs | B12: Banque Pop | C12: jeunes actifs | D12: 695743 | E12: au quotidien | F12: 3916 | G12: emprunter | H12: baseform | I12: 163289 | J12: formulaire | K12: sim auto express | N12: 1042 | O12: acheter votre résidence principale | P12: 3083 | R12: assurance auto | S12: 23657 | T12: assurance voyage | W12: =CONCATENATE(U12," ",V12) | AD12: contact conseiller email | AE12: suivant | AF12: 3942 | AG12: rechercher
A13: institutionnels | B13: deep purple | C13: institutionnels | D13: 588867 | E13: candidature | F13: 51 | G13: epargner | H13: basepageedito | I13: 17 | J13: gammes | K13: credit conso demande | N13: 706 | O13: acquérir pour louer | P13: 1072 | R13: assurance auto assur-bp auto | S13: 44 | T13: bourse | W13: =CONCATENATE(U13," ",V13) | AD13: suivant | AE13: telechargement | AF13: 3250 | AG13: sortie
A14: fonctionnaires | C14: fonctionnaires | D14: 498700 | E14: compte | F14: 469 | G14: financement | H14: beneficiaires | I14: 472151 | J14: home | K14: sim perso auto | N14: 380 | O14: acquérir votre voiture | P14: 428 | R14: assurance famille | S14: 3409 | T14: carte | W14: =CONCATENATE(U14," ",V14) | AD14: en detail | AE14: sortie | AF14: 2579 | AG14: telechargement
A15: banque privée | C15: banque privée | D15: 399238 | E15: Comptes | F15: 929421 | G15: gestion privee | H15: carte | I15: 527216 | J15: information | K15: opposition en ligne carte | N15: 374 | O15: acquisition cession transmission | P15: 29 | R15: assurance mrh | S15: 3570 | T15: cat | W15: =CONCATENATE(U15," ",V15) | AD15: historique virement | AE15: activer | AF15: 1917 | AG15: valider
A16: artisan commerçant | C16: artisan commerçant | D16: 300904 | E16: concrétiser son projet | F16: 145 | G16: ma banque pratique | H16: communique | I16: 5 | J16: marche | K16: modification email | N16: 351 | O16: activité au quotidien | P16: 18 | R16: assurance multirisque professionnelle | S16: 459 | T16: cel | W16: =CONCATENATE(U16," ",V16) | AD16: autre charge non | AE16: … | AG16: vignette
A17: service public | C17: service public | D17: 286061 | E17: connexion | F17: 569 | G17: ma synthese | H17: consultation | I17: 2924 | J17: operation | K17: sous cyberplus | N17: 299 | O17: affacturage | P17: 14 | R17: assurance obseques | S17: 568 | T17: cfn | W17: =CONCATENATE(U17," ",V17) | AD17: personnalisation label | AE17: …
A18: bfc banque privée | C18: bfc banque privée | D18: 278138 | E18: contact | F18: 106381 | G18: mes assurances | H18: contact | I18: 16722 | J18: page_ccd | K18: sous carte | N18: 116 | O18: aider mes proches | P18: 137 | R18: assurance proprietaire non occupant | S18: 406 | T18: compte-courant | W18: =CONCATENATE(U18," ",V18) | AD18: cartes et services
A19: entreprise | C19: entreprise | D19: 207726 | E19: credit | F19: 143510 | G19: mes cartes et paiement | H19: contenu animation transactionnelle | I19: 1797015 | J19: popin | K19: sim habitat express | N19: 103 | O19: aider vos proches | P19: 68 | R19: assurance rapatriement de corps | S19: 51 | T19: credit conso auto | W19: =CONCATENATE(U19," ",V19) | AD19: statut proprietaire
A20: professionnel | C20: professionnel | D20: 189990 | E20: crédit | F20: 9899 | G20: mes comptes | H20: coordonnees | I20: 88 | J20: produit | K20: sim habitat perso | N20: 42 | O20: améliorer la vie au quotidien | P20: 27 | R20: assurance responsabilite civile du celibataire | S20: 155 | T20: credit conso etudiant | W20: =CONCATENATE(U20," ",V20) | AD20: achat ancien
A21: agriculteurs | C21: agriculteurs | D21: 165032 | E21: créer | F21: 1813 | G21: mes credits | H21: coordoonnees | I21: 24048 | J21: profil | K21: sim frais notaire | N21: 29 | O21: améliorer leur quotidien | P21: 345 | R21: assurance synergie | S21: 104 | T21: credit conso travaux | W21: =CONCATENATE(U21," ",V21) | AD21: recherche
A22: enfants etudiants apprentis | C22: enfants etudiants apprentis | D22: 93562 | E22: découvrir bfc banque privée | F22: 961 | G22: messagerie | H22: credit pro | I22: 21628 | J22: recherche | K22: modification numero fixe | N22: 14 | O22: aménagement spécifique | P22: 102 | R22: assurance vehicules divers | S22: 502 | T22: credit conso tresorie | W22: =CONCATENATE(U22," ",V22) | AD22: achat maison
A23: franchise | C23: franchise | D23: 90682 | E23: défiscaliser | F23: 21 | G23: mon agence | H23: ctformcontactadvisor | I23: 2597 | J23: recherche agence | K23: en savoir plus | N23: 11 | O23: analyser votre patrimoine | P23: 44 | R23: assurance vie | S23: 74 | T23: credit immo | W23: =CONCATENATE(U23," ",V23) | AD23: …
A24: lycéens etudiants apprentis | C24: lycéens etudiants apprentis | D24: 83819 | E24: développer | F24: 87 | G24: mon coffre fort | H24: ctmobileredirect | I24: 9 | J24: univers | K24: sim cel | N24: 2 | O24: apprendre à gérer son budget | P24: 135 | R24: assurance vie horizeo | S24: 2505 | T24: credit immo primo | W24: =CONCATENATE(U24," ",V24) | AD24: …
A25: 16 ans et plus | C25: 16 ans et plus | D25: 83029 | E25: développer votre patrimoine | F25: 5522 | G25: mon epargne | H25: demo | I25: 15 | K25: sim prevoyance pro | N25: 2 | O25: apprendre à gérer votre budget | P25: 61 | R25: assur-bp auto | S25: 162 | T25: credit pro | W25: =CONCATENATE(U25," ",V25) | AD25: …
A26: 16-28 ans | C26: 16-28 ans | D26: 60594 | E26: digital briefcase | F26: 9154 | G26: mon profil | H26: detail de compte | I26: 50 | K26: sim retraite | N26: 2 | O26: assurance | P26: 310 | R26: assur-bp auto des particuliers | S26: 5775 | T26: eparfix | W26: =CONCATENATE(U26," ",V26)
A27: profession libérale | C27: profession libérale | D27: 57093 | E27: document | F27: 225867 | G27: parametres | H27: dossier client | I27: 3473 | K27: sim impot sur revenu | N27: 1 | O27: assurance de personnes | P27: 8687 | R27: assur-bp auto du pro | S27: 237 | T27: gav | W27: =CONCATENATE(U27," ",V27)
A28: jeune actif | C28: jeune actif | D28: 55926 | E28: edito | F28: 21074220 | G28: placement | H28: dossier client - produit | I28: 395 | K28: sim pel | N28: 1 | O28: assurance de responsabilité | P28: 78 | R28: assur-bp camping-car ambulance bazar forain vehicule de collection | S28: 112 | T28: internet | W28: =CONCATENATE(U28," ",V28)
A29: agriculture – viticulture | C29: agriculture – viticulture | D29: 31049 | E29: emprunter | F29: 384695 | G29: politique sociale | H29: editorial | I29: 1508572 | K29: sim madelin | N29: 1 | O29: assurance des appareils nomades | P29: 787 | R29: assur-bp enfant | S29: 1185 | T29: ldd | W29: =CONCATENATE(U29," ",V29)
A30: agriculteur viticulteur | C30: agriculteur viticulteur | D30: 29603 | E30: encaisser et payer | F30: 152 | G30: prelevements | H30: erreur | I30: 101837 | K30: souscription auto | O30: assurance des biens | P30: 201 | R30: assur-bp habitat | S30: 4326 | T30: lep | W30: =CONCATENATE(U30," ",V30)
A31: frontalier | C31: frontalier | D31: 24287 | E31: enfants | F31: 599 | G31: virements | H31: etablissement | I31: 71 | K31: sim prevoyance | O31: assurance des comptes | P31: 1471 | R31: assur-bp horizon | S31: 1045 | T31: livret a | W31: =CONCATENATE(U31," ",V31)
A32: associations et institutionnels | C32: associations et institutionnels | D32: 22608 | E32: épargne | F32: 6487 | H32: expertise | I32: 2 | K32: sim droit succession | O32: assurance des habitations | P32: 8704 | R32: assur-bp moto | S32: 481 | T32: livret b | W32: =CONCATENATE(U32," ",V32)
A33: apprentisetudiants | C33: apprentisetudiants | D33: 19019 | E33: epargner | F33: 37612 | H33: formulaire | I33: 286321 | K33: sim fiscal perp | O33: assurance des moyens de paiement | P33: 631 | R33: assur-bp sante | S33: 814 | T33: livret grand format | W33: =CONCATENATE(U33," ",V33)
A34: etudiants | C34: etudiants | D34: 18859 | E34: épargner | F34: 58453 | H34: gammes | I34: 176543 | K34: modification numero mobile | O34: assurance des personnes | P34: 782 | R34: assur-bp sante collective | S34: 50 | T34: livret grand prix | W34: =CONCATENATE(U34," ",V34)
A35: agriculteurs viticulteurs | C35: agriculteurs viticulteurs | D35: 18067 | E35: expertiser | F35: 6 | H35: historique | I35: 244219 | K35: sim isf | O35: assurance des véhicules | P35: 8898 | R35: assur-bp sante profil pro | S35: 69 | T35: livret jeune | W35: =CONCATENATE(U35," ",V35)
A36: institutionnels associations | C36: institutionnels associations | D36: 11861 | E36: financer | F36: 14566 | H36: home | I36: 13922930 | K36: sim credit immo PTZ | O36: assurance iard | P36: 27227 | R36: assurez votre activite professionnelle | S36: 42 | T36: obseques | W36: =CONCATENATE(U36," ",V36)
A37: associations | C37: associations | D37: 9774 | E37: financer vos projets | F37: 9 | H37: i-frame | I37: 2 | O37: assurance véhicules divers | P37: 74 | R37: atlantique bail plaisance | S37: 66 | T37: opcvm | W37: =CONCATENATE(U37," ",V37)
A38: jeunes adultes | C38: jeunes adultes | D38: 6942 | E38: flux | F38: 755 | H38: landing page | I38: 209 | O38: assurance vie | P38: 7377 | R38: autonomis | S38: 206 | T38: paiement | W38: =CONCATENATE(U38," ",V38)
A39: collégiens etudiants apprentis | C39: collégiens etudiants apprentis | D39: 3961 | E39: flux et trésorerie | F39: 480 | H39: page | I39: 51285 | O39: assurance vie : les atouts d un « bon contrat » | P39: 30 | R39: autorisation de decouvert | S39: 69 | T39: pea | W39: =CONCATENATE(U39," ",V39)
A40: 0-15 ans | C40: 0-15 ans | D40: 3182 | E40: gérer | F40: 64570 | H40: page daide cyber | I40: 20689 | O40: assurance vie capi pour optimiser vos placements | P40: 13 | R40: autorisation de decouvert acef | S40: 60 | T40: pel | W40: =CONCATENATE(U40," ",V40)
A41: enfants - étudiants - apprentis | C41: enfants - étudiants - apprentis | D41: 3181 | E41: gerer au quotidien | F41: 655 | H41: page darticle | I41: 2649 | O41: assurance vie et contrat de capitalisation | P41: 71 | R41: autorisations de decouvert | S41: 307 | T41: pj | W41: =CONCATENATE(U41," ",V41)
...

Sheet Datalayer BPCE vdef
A2: En cours de modification par Charlotte et Agathe (01/04/2020)
A6: Colonne2 | B6: ID | C6: Numéro variable AA | D6: Nom | E6: Description | F6: Présence d'une extension ou transco Tealium | G6: Statut | H6: Action | I6: Type de variable | J6: Variable datalayer | K6: Nomenclature datalayer | L6: Variable cookie | M6: Règle Tealium | N6: Scope evar | O6: Allocation | P6: Commentaire | Q6: Valeurs | R6: Classification | S6: Commentaire BP Hortense | T6: web composant transverse & datalayer 89c3 | U6: web CE | V6: web BP | W6: application CE | X6: application BP | Y6: Propiété | Z6: variable | AA6: Description2 | AB6: Description3 | AC6: Description4 | AD6: Description5 | AE6: Description6 | AF6: Description7 | AG6: Description8 | AH6: Description9 | AI6: Description10 | AJ6: Description11
A7: 1 | B7: Custom variable #1 | C7: prop1 | D7: Code Etablissement Client (prop1) | F7: X | G7: Validée | I7: Datalayer | N7: hit | T7: clients.idEnttGrpe | U7: client.idEnttGrpe | V7: clients.idEnttGrpe | W7: clients.idEnttGrpe | X7: clients.idEnttGrpe | Y7: clients | Z7: idEnttGrpe | AA7: "Contient le Code Etablissement de rattachement du Client (code interbancaire (CE) ou COTEB (BP) caractères), vide si prospect Règle de gestion : - récupération via BAPI - si BAPI pas présente/utilisable, récupération via un cookie (cookie le + récent) 1) CE : nom du cookie = ""ez_track"" et ""EZ_CONTEXTE"" et les valeurs sont : en mode identifié : ez_track = creg%3D{ne pas prendre}%26nab%3D%26nodape%3D{idclient} EZ_CONTEXTE = mar%3D{marcheclient}%26reg%3D{codeetablissement} en mode authentifié : cmar%3D{marcheclient}%26creg%3D{codeetablissement}%26nab%3D11a7723955fd8e2bba6a87cb42dd18dc%26nodape%3D{idclient} ex:ez_track identifié : creg%3D11315%26nab%3D48543044ddffb3ec7177aec5154655b9%26nodape%3D907562536 ez_track authentifié : cmar%3D101%26creg%3D17515%26nab%3D11a7723955fd8e2bba6a87cb42dd18dc%26nodape%3D065584064 EZ_CONTEXTE : mar%3D101%26reg%3D17515 2) BP : Il s’agit du cookie « tealiumClientDataCookie », dont la valeur correspond à : idclient-marche- idEnttGrpe"
A8: 2 | B8: Custom variable #2 | C8: prop2 | D8: Id Client (prop2) | F8: X | G8: Documentation à modifier (89c3 - performance digitale) | I8: Datalayer | N8: hit | T8: clients.id | U8: client.id | V8: clients.id | W8: clients.clientid | X8: clients.clientid | Y8: clients | Z8: clientid | AA8: "Identifiant validé juridiquement et au niveau de la sécurité comme donnée non personnelle et non sensible qui peut être envoyé à des prestataires externes pour des campagnes marketing digital. CE : contient l’identifiant Client MySys (NODAPE) du client authentifié ou identifié. Donnée numérique sur 7 ou 9 caractères contenant les « 0 » non significatifs. BP : COTE identifiant numérique sur 10 caractères Règle de gestion : - récupération via BAPI - si BAPI pas présente, récupération via un cookie (cookie le + récent) 1) CE : nom du cookie = ""ez_track"" et ""EZ_CONTEXTE"" et les valeurs sont : en mode identifié : ez_track = creg%3D{ne pas prendre}%26nab%3D%26nodape%3D{idclient} EZ_CONTEXTE = mar%3D{marcheclient}%26reg%3D{codeetablissement} en mode authentifié : cmar%3D{marcheclient}%26creg%3D{codeetablissement}%26nab%3D11a7723955fd8e2bba6a87cb42dd18dc%26nodape%3D{idclient} ex:ez_track identifié : creg%3D11315%26nab%3D48543044ddffb3ec7177aec5154655b9%26nodape%3D907562536 ez_track authentifié : cmar%3D101%26creg%3D17515%26nab%3D11a7723955fd8e2bba6a87cb42dd18dc%26nodape%3D065584064 EZ_CONTEXTE : mar%3D101%26reg%3D17515 2) BP : Il s’agit du cookie « tealiumClientDataCookie », dont la valeur correspond à : idclient-marche- idEnttGrpe"
A9: 3 | B9: Custom variable #3 | C9: prop3 | D9: Statut Client (prop3) | G9: Validée | H9: X | I9: Datalayer | N9: hit | T9: clients.status | U9: client.statut | V9: clients.statut | W9: clients.statut | X9: clients.statut ET clients.clientStatus | Y9: clients | Z9: statut | AA9: "Contient le niveau de connaissance du client. Authentifié = logué dans la session Identifié = logué dans une session antérieure Prospect = jamais connecté côté CE - Authentifié : cookie ez-track est présent et le cookie SES est présent et possède la valeur auth=1  renvoyer les valeurs du cookie ez-track selon le découpage en règle de gestion sharepoint pour prop1, 2, 4 et pour prop3 valoriser en dur « authentifié » - Identifié : cookie ez-track est présent et le cookie SES est présent et possède la valeur auth=0  renvoyer les valeurs du cookie ez-track selon le découpage en règle de gestion sharepoint pour prop1, 2, 4 et pour prop3 valoriser en dur « identifié » - Prospect : cookie ez-track n’existe pas  ne pas valoriser prop1, 2, 4, mais valoriser prop3 en dur à « prospect » Côté BP - Authentifié : cookie TealiumIDUser est présent et tealiumClientDatacookie présent  renvoyer les valeurs du cookie tealiumClientDatacookie selon le découpage en règle de gestion sharepoint pour prop1, 2, 4 et pour prop3 valoriser en dur « authentifié » - Identifié : cookie tealiumClientDatacookie est présent et TealiumIDUser absent  renvoyer les valeurs du cookie tealiumClientDatacookie selon le découpage en règle de gestion sharepoint pour prop1, 2, 4 et pour prop3 valoriser en dur « identifié » - Prospect : cookie TealiumIDUser et tealiumClientDataCookie ne sont pas présents  ne pas valoriser prop1, 2, 4, mais valoriser prop3 en dur à « prospect » "
A10: 4 | B10: Custom variable #4 | C10: prop4 | D10: Marché Client (prop4) | F10: X | I10: Datalayer | N10: hit | T10: clients.marche | U10: client.marche | V10: clients.marche | W10: clients.marche | X10: clients.marche | Y10: clients | Z10: marche | AA10: "Contient le marché du client authentifié ou identifié, vide si prospect Règle de gestion : - récupération via BAPI - si BAPI pas présente, récupération via un cookie (cookie le + récent) 1) CE : nom du cookie = ""ez_track"" et ""EZ_CONTEXTE"" et les valeurs sont : en mode identifié : ez_track = creg%3D{ne pas prendre}%26nab%3D%26nodape%3D{idclient} EZ_CONTEXTE = mar%3D{marcheclient}%26reg%3D{codeetablissement} en mode authentifié : cmar%3D{marcheclient}%26creg%3D{codeetablissement}%26nab%3D11a7723955fd8e2bba6a87cb42dd18dc%26nodape%3D{idclient} ex:ez_track identifié : creg%3D11315%26nab%3D48543044ddffb3ec7177aec5154655b9%26nodape%3D907562536 ez_track authentifié : cmar%3D101%26creg%3D17515%26nab%3D11a7723955fd8e2bba6a87cb42dd18dc%26nodape%3D065584064 EZ_CONTEXTE : mar%3D101%26reg%3D17515 2) BP : Il s’agit du cookie « tealiumClientDataCookie », dont la valeur correspond à : idclient-marche- idEnttGrpe"
A11: 5 | B11: Custom variable #5 | C11: prop5 | D11: Code réduit Etablissement de la page (prop5) | F11: X | G11: Documentation à modifier (89c3 - performance digitale) | I11: Datalayer | N11: hit | T11: pages.CodeEnttGrpe | U11: page.CodeEnttGrpe | V11: pages.CodeEnttGrpe | W11: pages.codeEnttGrpe | X11: pages.codeEnttGrpe | Y11: pages | Z11: CodeEnttGrpe | AA11: "Code réduit de l'établissement de rattachement de la page Format : - 5 lettres pour CE (CEPAC, CEAULS...) - 3 chiffres pour BP (038, 552...)"
A12: 6 | B12: Custom variable #6 | C12: prop6 | D12: Type Applicatif (prop6) | G12: Validée | I12: Datalayer | N12: hit | T12: pages.applicationType | U12: page.applicationType | V12: pages.applicationType | W12: pages.applicationType | X12: pages.applicationType | Y12: pages | Z12: applicationType | AA12: Permet de distinguer de le type d'applicatif à l'origine du tag
A13: 7 | B13: Custom variable #7 | C13: prop7 | D13: Nom de l applicatif (prop7) | G13: Validée | I13: Datalayer | N13: hit | T13: pages.applicationName | U13: page.applicationName | V13: pages.applicationName | W13: pages.applicationName | X13: pages.applicationName | Y13: pages | Z13: applicationName | AA13: Permet de distinguer de quel applicatif provient le tag
A14: 8 | B14: Custom variable #8 | C14: prop8 | D14: Marché de navigation (prop8) | G14: Validée | H14: ? | I14: Datalayer | N14: hit | T14: pages.marche | U14: page.marche | V14: pages.marche | W14: pages.marche | X14: pages.marche | Y14: pages | Z14: marche | AA14: Correspond au marché en cours lors de la navigation
A15: 9 | B15: Custom variable #9 | C15: prop9 | D15: Univers de Navigation (prop9) | G15: Documentation à modifier (89c3 - performance digitale) | H15: Catégorisations à préciser | I15: Datalayer | N15: hit | P15: 88 valeurs, ne correspondant pas à l'attendu (probablement objet d'un scrapping) | S15: ok | T15: pages.univers | U15: page.univers | V15: pages.univers | W15: pages.univers | X15: pages.univers | Y15: pages | Z15: univers | AA15: Nom de l’univers en cours lors de la navigation (nom de l'onglet de navigation)
A16: 10 | B16: Custom variable #10 | C16: prop10 | D16: Type de la page (prop10) | G16: Documentation à modifier (89c3 - performance digitale) | H16: Catégorisations à préciser | I16: Datalayer | N16: hit | P16: inutilisable d'un point de vue analyse à cause de la diversité des valeurs | S16: ok | T16: pages.pageType | U16: page.pageType | V16: pages.pageType | W16: pages.pageType | X16: pages.pageType | Y16: pages | Z16: pageType | AA16: Type de la page
A17: 11 | B17: Custom variable #11 | C17: prop11 | D17: is ABTesting (prop11) | G17: Validée | I17: Kameleoon | N17: hit | S17: ok | T17: NA | U17: NA | V17: NA | W17: NA | X17: NA | AA17: ABTesting : nom du test ab - variable remplie par Kameleoon
A18: 12 | B18: Custom variable #12 | C18: prop12 | D18: Id ABTesting(prop12) | G18: Validée | I18: Kameleoon | N18: hit | T18: NA | U18: NA | V18: NA | W18: NA | X18: NA | AA18: ABTesting : nom du test ab - variable remplie par Kameleoon
A19: 13 | B19: Custom variable #13 | C19: prop13 | D19: Url de la page (prop13) | G19: Validée | I19: Tealium | N19: hit | P19: Variable Tealium pas implémentée partout | S19: ok | T19: NA | U19: NA | V19: NA | W19: NA | X19: NA | AA19: Url de la Page
A20: 14 | B20: Custom variable #14 | C20: prop14 | D20: Nom du Formulaire (prop14) | G20: Validée | I20: Datalayer | N20: hit | P20: Variable pas implémentée partout | S20: ok | T20: form.nom | U20: form.nom | Y20: form | Z20: nom | AA20: Nom du formulaire
A21: 15 | B21: Custom variable #15 | C21: prop15 | D21: Identifiant etape Formulaire (prop15) | G21: Validée | I21: Datalayer | N21: hit | P21: Valeurs à vocation à être adaptative | S21: ok | T21: form.idEtape | U21: form.idEtape | Y21: form | Z21: idEtape | AA21: Identifiant étape
A22: 16 | B22: Custom variable #16 | C22: prop16 | D22: Objet de l applicatif (prop16) | G22: Validée | I22: Datalayer | N22: hit | P22: Variable pas implémentée partout, action côté webmestres et côté développeurs pour remplir les champs CMS ou les projets | S22: : Nous avons très peu de codes produits qui remontent seulement 1 par produit en semaine ? | T22: pages.espace | U22: page.espace | V22: pages.espace | W22: pages.espace | X22: pages.espace | Y22: pages | Z22: espace | AA22: Type de l'application (commercial = portail, transactionnel = espace connecté)
A23: 17 | B23: Custom variable #17 | C23: prop17 | D23: Gamme de produit de Navigation (prop17) | G23: Documentation à modifier (89c3 - performance digitale) | H23: Catégorisations à préciser, règle de gestion à renseigner | I23: Datalayer | N23: hit | P23: Variable pas implémentée partout, action côté webmestres et côté développeurs pour remplir les champs CMS ou les projets | S23: Pas de données | T23: produits.gamme | U23: produit.gamme | V23: produits.gamme | Y23: produits | Z23: gamme | AA23: Gamme de produit dont traite la page (au sens métier) (liste non exhaustive)
A24: 18 | B24: Custom variable #18 | C24: prop18 | D24: Code Produit de navigation (prop18) | G24: Documentation à modifier (89c3 - performance digitale) | H24: Catégorisations à préciser, règle de gestion à renseigner | I24: Datalayer | N24: hit | P24: Variable pas implémentée partout, action côté webmestres et côté développeurs pour remplir les champs CMS ou les projets | S24: ok | T24: produits.code | U24: produit.code | V24: produits.code | Y24: produits | Z24: code | AA24: Code du produit dont traite la page (au sens métier) (liste non exhaustive)
A25: 20 | B25: Custom variable #20 | C25: prop24 | D25: type de dossier (prop20) | G25: Validée | I25: Datalayer | N25: hit | T25: pages.TypeDossier | U25: page.TypeDossier | Y25: pages | Z25: TypeDossier | AA25: Type de dossier selectionné dans le portail KYC- connaissance client
A26: 21 | B26: Custom variable #21 | C26: prop31 | D26: Page | G26: Validée | H26: OK Octobre 2019 | I26: Tealium | N26: hit | T26: NA | U26: NA | V26: NA | W26: NA | X26: NA | Y26: pages | Z26: pageName | AA26: Page pour les clics, ne pas implémenter sur les évènements pages vues, implémenter uniquement sur les click event.
A27: 22 | B27: Custom variable #22 | C27: prop32 | D27: Pagename page précédente (prop32) | G27: Validée | I27: Tealium | N27: hit | T27: NA | U27: NA | V27: NA | W27: NA | X27: NA | AA27: Donne le pagename précédent sur les évènements de page, et donne le pagename de navigation pour un click event. Ne fonctionne pas sur les parcours non passés sous Tealium.
A28: 23 | B28: Custom variable #23 | C28: prop35 | D28: Nombre de cartes actives differentes (prop35) | G28: Validée | I28: Datalayer | N28: hit | T28: custom.NombreCartesActives | V28: custom.NombreCartesActives | W28: custom.NombreCartesActives | X28: custom.NombreCartesActives | Y28: custom | Z28: NombreCartesActives | AA28: (pilotage de la carte) deep purple - page carrousel
A29: 24 | B29: Custom variable #24 | C29: prop36 | D29: Nombre de cartes opposées différentes (prop36) | G29: Validée | I29: Datalayer | N29: hit | T29: custom.NombreCartesOpposees | V29: custom.NombreCartesOpposees | W29: custom.NombreCartesOpposees | X29: custom.NombreCartesOpposees | Y29: custom | Z29: NombreCartesOpposees | AA29: (pilotage de la carte) deep purple - page carrousel
A30: 25 | B30: Custom variable #25 | C30: prop37 | D30: Nombre de cartes commandées ou expédiées (prop37) | G30: Validée | I30: Datalayer | N30: hit | T30: custom.NombreCartesCommandees | V30: custom.NombreCartesCommandees | W30: custom.NombreCartesCommandees | X30: custom.NombreCartesCommandees | Y30: custom | Z30: NombreCartesCommandees | AA30: (pilotage de la carte) deep purple - page carrousel
A31: 26 | B31: Custom variable #26 | C31: prop38 | D31: Nombre de cartes actives et verrouillées temporairement (prop38) | G31: Validée | I31: Datalayer | N31: hit | T31: custom.NombreCartesVerrouilleesTemp | V31: custom.NombreCartesVerrouilleesTemp | W31: custom.NombreCartesVerrouilleesTemp | X31: custom.NombreCartesVerrouilleesTemp | Y31: custom | Z31: NombreCartesVerrouilleesTemp | AA31: (pilotage de la carte) deep purple - page carrousel
A32: 27 | B32: Custom variable #27 | C32: prop39 | D32: Nombre de cartes actives et paiements en ligne désactivés (prop39) | G32: Validée | I32: Datalayer | N32: hit | T32: custom.NombreCartesPaiementDistanceOFF | V32: custom.NombreCartesPaiementDistanceOFF | W32: custom.NombreCartesPaiementDistanceOFF | X32: custom.NombreCartesPaiementDistanceOFF | Y32: custom | Z32: NombreCartesPaiementDistanceOFF | AA32: (pilotage de la carte) deep purple - page carrousel
A33: 28 | B33: Custom variable #28 | C33: prop40 | D33: Nombre de cartes actives et paiements a l etranger desactivés (prop40) | G33: Validée | I33: Datalayer | N33: hit | T33: custom.NombreCartesPaiementEtrangerOFF | V33: custom.NombreCartesPaiementEtrangerOFF | W33: custom.NombreCartesPaiementEtrangerOFF | X33: custom.NombreCartesPaiementEtrangerOFF | Y33: custom | Z33: NombreCartesPaiementEtrangerOFF | AA33: (pilotage de la carte) deep purple - page carrousel
A34: 29 | B34: Custom variable #29 | C34: prop41 | D34: Nombre de cartes enrolement | G34: Validée | I34: Datalayer | N34: hit | T34: custom.NbCartesEnrolement | V34: custom.NbCartesEnrolement | W34: custom.NbCartesEnrolement | X34: custom.NbCartesEnrolement | Y34: custom | Z34: NbCartesEnrolement | AA34: (pilotage de la carte) deep purple - page choix des cartes à enroler (parcours enrolement paylib)
A35: 30 | B35: Custom variable #30 | C35: prop45 | D35: Total nombre de compte détenus | G35: Validée | I35: Datalayer | N35: hit | T35: custom.nombreComptes | U35: custom.nombreComptes | V35: custom.nombreComptes | W35: custom.nombreComptes | X35: custom.nombreComptes | Y35: custom | Z35: nombreComptes | AA35: selfcare: page synthese, remonte le nombre de compte détenus par l'utilisateur (courant, epargne, financiere)
A36: 31 | B36: Custom variable #31 | C36: prop47 | D36: libelle transaction incorrect | G36: Validée | I36: Datalayer | N36: hit | T36: custom.libelleIncorrect | U36: custom.libelleIncorrect | V36: custom.libelleIncorrect | W36: custom.libelleIncorrect | X36: custom.libelleIncorrect | Y36: custom | Z36: libelleIncorrect | AA36: Mes Comptes : sur ecran detail d'une transaction, si l'user clique sur "libelle erroné", remonte les 5 qualificatifs suivants[ [originalText;sub_text;transactionTypeCode; external_merchant_identifier; transaction_date]
A37: 32 | B37: Custom variable #32 | C37: prop48 | D37: switch | G37: Validée | H37: Préciser la description | I37: Datalayer | N37: hit | T37: custom.switch | U37: custom.switch | V37: custom.switch | W37: custom.switch | X37: custom.switch | Y37: custom | Z37: switch | AA37: securpass enrolement - choix on ou off sur la page "enrolement - [touch id/fingerprint/faceid]
A38: 33 | B38: Custom variable #33 | C38: prop49 | D38: numero de contrat (natixis) | G38: Validée | H38: Préciser la description | I38: Non défini ou implémenté | N38: hit | T38: custom.numeroContrat | U38: custom.numeroContrat | V38: custom.numeroContrat | W38: custom.numeroContrat | X38: custom.numeroContrat | Y38: custom | Z38: numeroContrat | AA38: (parcours natixis virement credit renouvelable) pousser le numero de contrat associé au credit renouvelable du client en question (id coté natixis)
A39: 34 | B39: Custom variable #34 | C39: prop50 | D39: version tealium | G39: Validée | H39: Préciser la description | I39: Tealium | N39: hit | T39: NA | U39: NA | V39: NA | W39: NA | X39: NA | AA39: Variable générée par Tealium (pas datalayer). Concatène le nom du compte Tealium, le profil, l'environnement et la version pour chaque hit. Permet de vérifier le déploiement correct de Tealium et de pointer une version particulière en cas de bug
A40: 40 | B40: Custom variable #35 | C40: prop51 | D40: Code établissement page (prop51) | G40: Validée | H40: Préciser la description | I40: Datalayer | N40: hit | T40: NA | U40: NA | V40: NA | W40: NA | X40: NA | Y40: custom | AA40: Correspond au code établissement de rattachement de client en Lettres
A41: 35 | B41: Custom variable #36 | C41: prop52 | D41: Code banque/reseau client (prop52) | G41: Validée | H41: Préciser la description | I41: Tealium | N41: hit | P41: Mettre à jour documentation (Natixis ?) | T41: clients.idGrpe | U41: clients.idGrpe | V41: clients.idGrpe | W41: clients.idGrpe | X41: clients.idGrpe | Y41: clients | Z41: idGrpe
A42: 36 | B42: Custom variable #37 | C42: prop53 | D42: ID Client Natixis Assurances (prop53) | G42: Validée | H42: Préciser la description | I42: Non défini ou implémenté | N42: hit | P42: Mettre à jour documentation (Natixis ?) | T42: clients.idClientNxs | U42: clients.idClientNxs | V42: clients.idClientNxs | W42: clients.idClientNxs | X42: clients.idClientNxs | Y42: clients | Z42: idClientNxs
A43: 37 | B43: Custom variable #38 | C43: prop54 | D43: Timestamp | G43: Validée | H43: Préciser la description | I43: Non défini ou implémenté | N43: hit | T43: NA | U43: NA | V43: NA | W43: NA | X43: NA | AA43: Date et heure du hit
A44: 38 | B44: Custom variable #39 | C44: prop74 | D44: type opposition identification adresse IP | G44: Validée | H44: Préciser la description | I44: Tealium | N44: hit | P44: Revoir la pertinence métiers à long terme (IP dynamiques pour collaborateurs) | T44: custom.typeOpposition | U44: custom.typeOpposition | V44: custom.typeOpposition | W44: custom.typeOpposition | X44: custom.typeOpposition | Y44: custom | Z44: typeOpposition | AA44: Permet d'identifier les groupes d'IP à inclure/exclure des analyses
...

Sheet Datalayer BPCE vtravail
A1: Action | B1: Type de variable | C1: Scope evar | D1: Numéro | E1: Statut | F1: Pertinent (métiers et CRM) (O/N) | G1: Implémenté CE (O/N) | H1: Implémenté BP (O/N) | I1: Valeurs attendues (O/N) | J1: Commentaire | K1: Commentaire BP Hortense | L1: Nom | M1: Propiété | N1: variable | O1: Description | P1: Valeurs | Q1: Valeurs2 | R1: Valeurs3 | S1: Valeurs4 | T1: Valeurs5 | U1: Valeurs6 | V1: Valeurs7 | W1: Valeurs8 | X1: Valeurs9 | Y1: Valeurs10 | Z1: Valeurs11 | AA1: Valeurs12 | AB1: Valeurs13 | AC1: Valeurs14 | AD1: Valeurs15 | AE1: Valeurs16 | AF1: Valeurs17 | AG1: Valeurs18 | AH1: Valeurs19 | AI1: Valeurs20 | AJ1: Valeurs21 | AK1: Valeurs22 | AL1: Valeurs23 | AM1: Valeurs24 | AN1: Valeurs25 | AO1: Valeurs26 | AP1: Valeurs27 | AQ1: Valeurs28 | AR1: Valeurs29 | AS1: Valeurs30 | AT1: Valeurs31 | AU1: Valeurs32 | AV1: Valeurs33 | AW1: Valeurs34 | AX1: Valeurs35 | AY1: Valeurs36 | AZ1: Valeurs37 | BA1: Valeurs38 | BB1: Valeurs39 | BC1: Valeurs40 | BD1: Valeurs41
B2: prop | D2: 1 | E2: Validée | F2: O | G2: O | H2: Conserver | I2: O | K2: "sur BP: - les 14 premiers codes établissements sont à 3 chiffres le reste à 5 chiffres ( avec peu de connexions ) | L2: Code Etablissement Client (prop1) | M2: clients | N2: idEnttGrpe | O2: Description : Contient le Code Etablissement de rattachement du Client Format : (5 (CE) ou 3 (BP) caractères), Règle de gestion : rempli si client authentifié ou identifié, vide si prospect | P2: 16705 | Q2: 13335 | R2: 18715 | S2: 12135 | T2: 14445 | U2: 18315 | V2: 17515 | W2: 13485 | X2: 14505 | Y2: 14265 | Z2: 15135 | AA2: 13135 | AB2: 16275 | AC2: 11425 | AD2: 18025 | AE2: 11315 | AF2: 13825 | AG2: 99999 | AH2: 002 | AI2: 008 | AJ2: 009 | AK2: 019 | AL2: 035 | AM2: 038 | AN2: 039 | AO2: 046 | AP2: 047 | AQ2: 066 | AR2: 067 | AS2: 068 | AT2: 078 | AU2: 087 | AV2: 534 | AW2: 536 | AX2: 537 | AY2: 552
A3: Faire un état des lieux sur le COTE | B3: prop | D3: 2 | E3: Documentation à modifier (89c3 - performance digitale) | F3: O | G3: O | H3: Modifier | I3: O | J3: Faire un état des lieux sur le COTE | K3: Les COTE sont tous alpha numériques ( normal non ?) | L3: Id Client (prop2) | M3: clients | N3: clientid | O3: Identifiant validé juridiquement et au niveau de la sécurité comme donnée non personnelle et non sensible qui peut être envoyé à des prestataires externes pour des campagnes marketing digital. CE : contient l’identifiant Client MySys (NODAPE) du client authentifié ou identifié. Donnée numérique sur 7 ou 9 caractères contenant les « 0 » non significatifs. BP : COTE identifiant numérique sur 10 caractères
A4: Modifier référentiel | B4: prop | D4: 3 | E4: Validée | F4: O | G4: O | H4: Conserver | I4: O | J4: Préciser la règle de gestion (proposition dans le référentiel datalayer sharepoint) | K4: ok | L4: Statut Client (prop3) | M4: clients | N4: statut | O4: Contient le niveau de connaissance du client. Authentifié = logué dans la session Identifié = logué dans une session antérieure Prospect = jamais connecté | P4: authentifie | Q4: identifie | R4: prospect
A5: Homogénéiser les valeurs | B5: prop | D5: 4 | E5: Documentation à modifier (89c3 - performance digitale) | F5: O | G5: O | H5: Conserver | I5: N | J5: Casse et orthographe très différent (particuliers/Particulier/particulier/professionnel/Profesionel) : - soit anomalie dans chacun des applicatif, - soit majorité des retraitements gérés par composant transverse et modification peut être aisée ==> étude du composant transverse | K5: Marchés clients sont toujours à homogénéiser si possibles: - Particulier/ pParticuliers - Entreprise/ entreprises - il y a 4 types de professionnel/professionnels/profesionnel/ Professionnels Mapping Tealium, processing rule ? | L5: Marché Client (prop4) | M5: clients | N5: marche | O5: Contient le marché du client authentifié ou identifié, vide si prospect | P5: associations, fondations, mutuelles – mandataires judiciaires a la protection des majeurs | Q5: entreprises | R5: hors marche | S5: immobilier professionnel | T5: logement social - economie mixte | U5: particuliers | V5: professionnels | W5: secteur public | X5: fonction publique | Y5: sans comerçants | Z5: gestion privee | AA5: professions libérales | AB5: jeunes actifs | AC5: institutionnels | AD5: fonctionnaires | AE5: banque privée | AF5: service publique | AG5: bfc banque privée | AH5: agriculteurs | AI5: professions libérales | AJ5: lycéens étudiants apprentis | AK5: enfants étudiants apprentis | AL5: 16 ans et plus | AM5: franchise | AN5: jeune actif | AO5: 16-28 ans | AP5: viticulture | AQ5: frontaliers | AR5: institutionnels associations | AS5: associations | AT5: jeunes adultes | AU5: startup | AV5: professionels
A6: Homogénéiser les valeurs | B6: prop | D6: 5 | E6: Documentation à modifier (89c3 - performance digitale) | F6: O | G6: O | H6: Modifier | I6: N | J6: Différents orthographes de la variable datalayer | K6: codes établissements de la page - on retiendra le forma en chiffres pour le datalayer - des formats en lettres resteront pour la prop51 dans la majorité des projets " | L6: Code réduit Etablissement de la page (prop5) | M6: pages | N6: CodeEnttGrpe | O6: Code réduit de l'établissement de rattachement de la page, (Lettres pour CE, 3chiffres pour BP) | P6: CEALS | Q6: CEAPC | R6: CEAUL | S6: CEBFC | T6: CEBPL | U6: CECAZ | V6: CEIDF | W6: CELRO | X6: CELCE | Y6: CELDA | Z6: CELCA | AA6: CEMIP | AB6: CEHDF | AC6: CENOR | AD6: CEHDF | AE6: CEPAC | AF6: CERHA | AG6: CENAT | AH6: BPRI | AI6: BPBFC | AJ6: BPACA | AK6: BPAURA | AL6: BPN | AM6: BPATL | AN6: BPAURA | AO6: BPMED | AP6: BPALC | AQ6: BPS | AR6: BPO | AS6: BPAURA | AT6: BPOC | AU6: BPVF | AV6: CMMBN | AW6: CMMATL | AX6: CMMLSO | AY6: BQSAV
B7: prop | D7: 6 | E7: Validée | F7: O | G7: O | H7: Conserver | K7: ok | L7: Type Applicatif (prop6) | M7: pages | N7: applicationType | O7: Permet de distinguer de le type d'applicatif à l'origine du tag | P7: application | Q7: site
A8: A préciser référentiel | B8: prop | D8: 7 | E8: Validée | F8: O | G8: O | H8: Conserver | I8: O | J8: Préciser la mécanique : se base sur l'applicatif, ou bien sur le plan de marquage ? Ex : des pages PISP sont valorisées cyber | K8: ok | L8: Nom de l applicatif (prop7) | M8: pages | N8: applicationName | O8: Permet de distinguer de quel applicatif provient le tag (à mettre à jour avec les données BP) | P8: banque | Q8: ce net | R8: dea | S8: dei [part/pro] | T8: dei part | U8: dei pp | V8: dei pro | W8: dei sp | X8: dem | Y8: ecommerce | Z8: evi | AA8: harvest | AB8: mbl | AC8: ngi | AD8: tunnel
A9: ? | B9: prop | D9: 8 | E9: Validée | F9: O | G9: O | H9: Conserver | I9: N | J9: Différences de format et remontées inégales (côté BP et côté CE) | K9: "rajouté quelques valeurs BP dans le datalayer - startup, franchise, gestion privée, étudiant " | L9: Marché de navigation (prop8) | M9: pages | N9: marche | O9: Correspond au marché en cours lors de la navigation | P9: associations, fondations, mutuelles – mandataires judiciaires a la protection des majeurs | Q9: entreprises | R9: hors marche | S9: immobilier professionnel | T9: logement social - economie mixte | U9: particuliers | V9: professionnels | W9: secteur public
A10: Catégorisations à préciser | B10: prop | D10: 9 | E10: Documentation à modifier (89c3 - performance digitale) | F10: O | G10: O | H10: Conserver | I10: N | J10: 88 valeurs, ne correspondant pas à l'attendu (probablement objet d'un scrapping) | K10: ok | L10: Univers de Navigation (prop9) | M10: pages | N10: univers | O10: Nom de l’univers en cours lors de la navigation (nom de l'onglet de navigation) | P10: agences et distributeurs | Q10: assistance | R10: assurer | S10: au quotidien | T10: banque au quotidien et assurance | U10: connexion | V10: contact | W10: emprunter | X10: epargner | Y10: financement | Z10: gestion privee | AA10: ma banque pratique | AB10: ma synthese | AC10: mes assurances | AD10: mes cartes et paiement | AE10: mes comptes | AF10: mes credits | AG10: messagerie | AH10: mon agence | AI10: mon coffre fort | AJ10: mon epargne | AK10: mon profil | AL10: parametres | AM10: placement | AN10: politique sociale | AO10: prelevements | AP10: virements
A11: Catégorisations à préciser | B11: prop | D11: 10 | E11: Documentation à modifier (89c3 - performance digitale) | F11: O | G11: O | H11: Conserver | I11: N | J11: inutilisable d'un point de vue analyse à cause de la diversité des valeurs | K11: ok | L11: Type de la page (prop10) | M11: pages | N11: pageType | O11: Type de la page | P11: conseil | Q11: consultation | R11: contact | S11: document | T11: edito | U11: erreur | V11: faq | W11: formulaire | X11: gammes | Y11: home | Z11: information | AA11: marche | AB11: operation | AC11: page_ccd | AD11: popin | AE11: produit | AF11: profil | AG11: recherche | AH11: recherche agence | AI11: univers
B12: prop | D12: 11 | E12: Validée | F12: O | G12: O | H12: Conserver | K12: ok | L12: is ABTesting (prop11) | O12: ABTesting : nom du test ab - variable remplie par Kameleoon
B13: prop | D13: 12 | E13: Validée | F13: O | G13: O | H13: Conserver | K13: ok | L13: Id ABTesting(prop12) | O13: ABTesting : nom du test ab - variable remplie par Kameleoon
A14: OK Octobre 2019 | B14: prop | D14: 13 | E14: Validée | F14: O | G14: O | H14: Conserver | I14: O | J14: Variable Tealium pas implémentée partout | K14: ok | L14: Url de la page (prop13) | O14: Url de la Page
A15: Demander si utilité du doublon en evar ? Ne pas supprimer car entraine des modifs de paramétrages importants | B15: prop | D15: 14 | E15: Validée | F15: O | G15: O | H15: Conserver | I15: O | J15: Variable pas implémentée partout | K15: ok | L15: Nom du Formulaire (prop14) | M15: form | N15: nom | O15: Nom du formulaire
A16: Demander si utilité du doublon en prop, si non ==> supprimer prop | B16: prop | D16: 15 | E16: Validée | F16: O | G16: O | H16: Conserver | I16: O | J16: Valeurs à vocation à être adaptative | K16: ok | L16: Identifiant etape Formulaire (prop15) | M16: form | N16: idEtape | O16: Identifiant étape
B17: prop | D17: 16 | E17: Validée | F17: O | G17: O | H17: Conserver | I17: N | J17: Variable pas implémentée partout, action côté webmestres et côté développeurs pour remplir les champs CMS ou les projets | K17: : Nous avons très peu de codes produits qui remontent seulement 1 par produit en semaine ? | L17: Objet de l applicatif (prop16) | M17: pages | N17: espace | O17: Type de l'application (commercial = portail, transactionnel = espace connecté) | P17: commercial | Q17: externe | R17: transactionnel | S17: interne
A18: Catégorisations à préciser, règle de gestion à renseigner | B18: prop | D18: 17 | E18: Documentation à modifier (89c3 - performance digitale) | F18: O | G18: O | H18: Conserver | I18: N | J18: Variable pas implémentée partout, action côté webmestres et côté développeurs pour remplir les champs CMS ou les projets | K18: Pas de données | L18: Gamme de produit de Navigation (prop17) | M18: produits | N18: gamme | O18: Gamme de produit dont traite la page (au sens métier) (liste non exhaustive) | P18: assurance | Q18: bancarisation | R18: credit conso | S18: credit immo | T18: credit pro | U18: epargne financiere | V18: epargne liquide | W18: service b2b | X18: service b2c
A19: Catégorisations à préciser, règle de gestion à renseigner | B19: prop | D19: 18 | E19: Documentation à modifier (89c3 - performance digitale) | F19: O | G19: O | H19: Conserver | I19: N | J19: Variable pas implémentée partout, action côté webmestres et côté développeurs pour remplir les champs CMS ou les projets | K19: ok | L19: Code Produit de navigation (prop18) | M19: produits | N19: code | O19: Code du produit dont traite la page (au sens métier) (liste non exhaustive) | P19: assepargne | Q19: assurance 2 roues | R19: assurance auto | S19: assurance emprunteur | T19: assurance moyen paiement | U19: assurance mrh | V19: assurance resp civile | W19: assurance voyage | X19: bourse | Y19: carte | Z19: cat | AA19: cel | AB19: cfn | AC19: compte-courant | AD19: credit conso auto | AE19: credit conso etudiant | AF19: credit conso travaux | AG19: credit conso tresorie | AH19: credit immo | AI19: credit immo primo | AJ19: credit pro | AK19: eparfix | AL19: gav | AM19: internet | AN19: ldd | AO19: lep | AP19: livret a | AQ19: livret b | AR19: livret grand format | AS19: livret grand prix | AT19: livret jeune | AU19: obseques | AV19: opcvm | AW19: paiement | AX19: pea | AY19: pel | AZ19: pj | BA19: retrait inter | BB19: sante | BC19: securmedia | BD19: visuel carte
B20: prop | D20: 19 | E20: A supprimer | F20: O | G20: O | H20: Conserver | I20: N | J20: 500K valeurs | L20: Nom de la tuile (prop19)
B21: prop | D21: 20 | E21: A supprimer | F21: O | G21: O | H21: Conserver | I21: N | J21: implémentée, mais inutilisable | L21: tags article utilises
A22: A supprimer, valeur seulement mappée pour la report suite BPACA, et côté CE, prop sur les vignettes mappée mais pas utilisée | B22: prop | D22: 21 | E22: A supprimer | F22: ? | G22: N | I22: ? | J22: redondant avec propclient et proppages | L22: Code établissement BP
B23: prop | D23: 22 | E23: A supprimer | F23: ? | G23: N | I23: N | J23: non implémentée, aucun référentiel de valeurs | L23: tags article utilises
A24: Voir utilité de la métrique Time spent on page pour les PO ? | B24: prop | D24: 23 | E24: A supprimer | L24: Temps de chargement de la page | M24: pages | N24: loadingTime
A25: Changer le nom de la variable Adobe | B25: prop | D25: 24 | E25: Validée | L25: type de dossier | M25: pages | N25: TypeDossier | O25: Type de dossier selectionné dans le portail KYC- connaissance client
B26: prop | D26: 25 | E26: A supprimer | F26: N | G26: O | I26: O | J26: Variables implémentées mais non utilisée par BPCE central et bientôt désuètes vs le nouveau plan de taggage INNOV2020 | L26: type de document | M26: pages | N26: TypeDocument | O26: type de document séléctionné dans le portail : KYC / Numairic | P26: kbis | Q26: bilan | R26: status | S26: declaration | T26: Beneficiaire effectif | U26: bilan du dernier excercice | V26: Bilan supplémentaire precedent | W26: bilan supplémentaire antérieur
B27: prop | D27: 26 | E27: A supprimer | F27: N | G27: O | I27: O | J27: Variables implémentées mais non utilisée par BPCE central et bientôt désuètes vs le nouveau plan de taggage INNOV2020 | L27: vide
B28: prop | D28: 27 | E28: A supprimer | F28: N | G28: O | I28: O | J28: Variables implémentées mais non utilisée par BPCE central et bientôt désuètes vs le nouveau plan de taggage INNOV2020 | L28: vide
B29: prop | D29: 28 | E29: A supprimer | F29: N | G29: O | I29: O | J29: Variables implémentées mais non utilisée par BPCE central et bientôt désuètes vs le nouveau plan de taggage INNOV2020 | L29: vide
B30: prop | D30: 29 | E30: A supprimer | F30: N | G30: O | I30: O | J30: Variables implémentées mais non utilisée par BPCE central et bientôt désuètes vs le nouveau plan de taggage INNOV2020 | L30: vide
A31: Créer un event de décompte résultat nul | B31: prop | D31: 30 | E31: A supprimer | F31: ? | L31: Résultat nul (prop30) | M31: custom | N31: resultatNul
A32: OK Octobre 2019 | B32: prop | D32: 31 | E32: Validée | F32: O | G32: O | H32: N | I32: N | J32: Valeurs à vocation à être adaptative Règle de gestion non précisée ==> non implémentée par Natixis dans leur Tealium | L32: page | M32: pages | N32: pageName | O32: Page pour les clics
A33: OK Octobre 2019 | B33: prop | D33: 32 | E33: Validée | F33: O | G33: N | H33: N | I33: NA | J33: Variable Tealium paramétrable | L33: pagename page précédente
